Traceback (most recent call last):
  File "C:\Python311\Lib\site-packages\jupyter_cache\executors\utils.py", line 58, in single_nb_execution
    executenb(
  File "C:\Python311\Lib\site-packages\nbclient\client.py", line 1314, in execute
    return NotebookClient(nb=nb, resources=resources, km=km, **kwargs).execute()
           ^^^^^^^^^^^^^^^^^^^^^^^^^^^^^^^^^^^^^^^^^^^^^^^^^^^^^^^^^^^^^^^^^^^^^
  File "C:\Python311\Lib\site-packages\jupyter_core\utils\__init__.py", line 165, in wrapped
    return loop.run_until_complete(inner)
           ^^^^^^^^^^^^^^^^^^^^^^^^^^^^^^
  File "C:\Python311\Lib\asyncio\base_events.py", line 650, in run_until_complete
    return future.result()
           ^^^^^^^^^^^^^^^
  File "C:\Python311\Lib\contextlib.py", line 222, in __aexit__
    await self.gen.athrow(typ, value, traceback)
  File "C:\Python311\Lib\site-packages\nbclient\client.py", line 654, in async_setup_kernel
    yield
  File "C:\Python311\Lib\site-packages\nbclient\client.py", line 709, in async_execute
    await self.async_execute_cell(
  File "C:\Python311\Lib\site-packages\nbclient\client.py", line 1062, in async_execute_cell
    await self._check_raise_for_error(cell, cell_index, exec_reply)
  File "C:\Python311\Lib\site-packages\nbclient\client.py", line 918, in _check_raise_for_error
    raise CellExecutionError.from_cell_and_msg(cell, exec_reply_content)
nbclient.exceptions.CellExecutionError: An error occurred while executing the following cell:
------------------
import numpy as np
from scipy.fft import fft, ifft, fftshift, ifftshift
import matplotlib.pyplot as plt
from ipywidgets import interact, Layout
import ipywidgets as widgets
from IPython.display import display, clear_output
import scipy.io
import io
import scipy
from scipy import signal
from scipy.io.wavfile import write
from IPython.display import display, Audio, clear_output
from scipy.signal import convolve, kaiser_atten, welch, remez, firwin2, freqz
import requests
import warnings
warnings.filterwarnings('ignore')
import time
print("Libraries added successfully!")

------------------


[1;31m---------------------------------------------------------------------------[0m
[1;31mModuleNotFoundError[0m                       Traceback (most recent call last)
Cell [1;32mIn[1], line 4[0m
[0;32m      2[0m [38;5;28;01mfrom[39;00m [38;5;21;01mscipy[39;00m[38;5;21;01m.[39;00m[38;5;21;01mfft[39;00m [38;5;28;01mimport[39;00m fft, ifft, fftshift, ifftshift
[0;32m      3[0m [38;5;28;01mimport[39;00m [38;5;21;01mmatplotlib[39;00m[38;5;21;01m.[39;00m[38;5;21;01mpyplot[39;00m [38;5;28;01mas[39;00m [38;5;21;01mplt[39;00m
[1;32m----> 4[0m [38;5;28;01mfrom[39;00m [38;5;21;01mipywidgets[39;00m [38;5;28;01mimport[39;00m interact, Layout
[0;32m      5[0m [38;5;28;01mimport[39;00m [38;5;21;01mipywidgets[39;00m [38;5;28;01mas[39;00m [38;5;21;01mwidgets[39;00m
[0;32m      6[0m [38;5;28;01mfrom[39;00m [38;5;21;01mIPython[39;00m[38;5;21;01m.[39;00m[38;5;21;01mdisplay[39;00m [38;5;28;01mimport[39;00m display, clear_output

[1;31mModuleNotFoundError[0m: No module named 'ipywidgets'

